Workbook

Sheet 00_사용법
A1: 팀별 로봇 미로 주행 실습 — 관찰 결과 기록표
A2: 출처: 선생님 공유 슬라이드 「팀별 로봇 미로 주행 — 보상 설계·cuVSLAM·Nav2 실습」
A4: 사용법
A5: • 탭 하나 = 슬라이드 표 하나. 탭 이름 앞 숫자가 슬라이드 번호예요.
A6: • 회색 칸 = 선생님 슬라이드 예시(M38 시연 값). 고치지 않아요.
A7: • 노란 칸 = 우리 팀이 실제로 관찰·측정해서 채우는 칸이에요.
A8: • 판정은 목록에서 고르기: 통과 / 보류 / 실패 / 미측정. 50_미로결과의 판정은 숫자를 넣으면 자동이에요.
A9: • 실물에서 재지 않고 가정한 값은 메모에 '가정'이라고 꼭 적어요 (슬라이드 2 완료 기준).
A10: • 같은 조건(seed·경로·초기 위치)에서 한 항목씩 바꿔 비교해요 (슬라이드 20).
A12: 입력 예시 (형식 참고용)
A13: 탭 | B13: 항목 | C13: 우리 로봇 설정값 | D13: 관찰·측정 결과 | E13: 판정 | F13: 근거(로그·영상·파일) | G13: 담당 | H13: 날짜 | I13: 메모
A14: 33_cuVSLAM조정 | B14: 추적이 끊김 | C14: 노출 auto, 1280×720 30fps | D14: 복도 코너에서 3회 끊김, 재획득 평균 1.2 s | E14: 보류 | F14: evidence/run3/vslam.log | G14: 김혜민 | H14: 2026-10-27 | I14: 무늬 없는 벽 구간. 바닥 무늬는 합성(가정)
A17: 목차와 진행 현황 (자동 집계)
A18: 탭 | B18: 슬라이드 | C18: 표 제목 | D18: 항목 수 | E18: 통과 | F18: 보류 | G18: 실패 | H18: 미측정 | I18: 기록률
A19: 02_완료기준 | B19: 2 | C19: 실습 목표·완료 기준 | D19: 6 | E19: =COUNTIF(02_완료기준!$E$5:$E$10,"통과") -> 0 | F19: =COUNTIF(02_완료기준!$E$5:$E$10,"보류") -> 0 | G19: =COUNTIF(02_완료기준!$E$5:$E$10,"실패") -> 0 | H19: =COUNTIF(02_완료기준!$E$5:$E$10,"미측정") -> 0 | I19: =IFERROR((E19+F19+G19+H19)/D19,0) -> 0
A20: 07_팀별변경 | B20: 7 | C20: 팀별 로봇: 그대로 복사하지 않을 값 | D20: 4 | E20: =COUNTIF(07_팀별변경!$G$5:$G$8,"통과") -> 0 | F20: =COUNTIF(07_팀별변경!$G$5:$G$8,"보류") -> 0 | G20: =COUNTIF(07_팀별변경!$G$5:$G$8,"실패") -> 0 | H20: =COUNTIF(07_팀별변경!$G$5:$G$8,"미측정") -> 0 | I20: =IFERROR((E20+F20+G20+H20)/D20,0) -> 0
A21: 11_보상1 | B21: 11 | C21: 보상 사례: 진행·시간·목표 도착 | D21: 8 | E21: =COUNTIF(11_보상1!$G$5:$G$12,"통과") -> 0 | F21: =COUNTIF(11_보상1!$G$5:$G$12,"보류") -> 0 | G21: =COUNTIF(11_보상1!$G$5:$G$12,"실패") -> 0 | H21: =COUNTIF(11_보상1!$G$5:$G$12,"미측정") -> 0 | I21: =IFERROR((E21+F21+G21+H21)/D21,0) -> 0
A22: 12_보상2 | B22: 12 | C22: 보상 사례: 항의 크기·관측·악용 | D22: 8 | E22: =COUNTIF(12_보상2!$G$5:$G$12,"통과") -> 0 | F22: =COUNTIF(12_보상2!$G$5:$G$12,"보류") -> 0 | G22: =COUNTIF(12_보상2!$G$5:$G$12,"실패") -> 0 | H22: =COUNTIF(12_보상2!$G$5:$G$12,"미측정") -> 0 | I22: =IFERROR((E22+F22+G22+H22)/D22,0) -> 0
A23: 13_보상3 | B23: 13 | C23: 보상 사례: 충돌·코너·우회 | D23: 8 | E23: =COUNTIF(13_보상3!$G$5:$G$12,"통과") -> 0 | F23: =COUNTIF(13_보상3!$G$5:$G$12,"보류") -> 0 | G23: =COUNTIF(13_보상3!$G$5:$G$12,"실패") -> 0 | H23: =COUNTIF(13_보상3!$G$5:$G$12,"미측정") -> 0 | I23: =IFERROR((E23+F23+G23+H23)/D23,0) -> 0
A24: 14_보상4 | B24: 14 | C24: 보상 사례: 진동·정체·설계 오류 | D24: 8 | E24: =COUNTIF(14_보상4!$G$5:$G$12,"통과") -> 0 | F24: =COUNTIF(14_보상4!$G$5:$G$12,"보류") -> 0 | G24: =COUNTIF(14_보상4!$G$5:$G$12,"실패") -> 0 | H24: =COUNTIF(14_보상4!$G$5:$G$12,"미측정") -> 0 | I24: =IFERROR((E24+F24+G24+H24)/D24,0) -> 0
A25: 17_PPO1 | B25: 17 | C25: PPO 튜닝: 업데이트·탐색·가치함수 | D25: 8 | E25: =COUNTIF(17_PPO1!$G$5:$G$12,"통과") -> 0 | F25: =COUNTIF(17_PPO1!$G$5:$G$12,"보류") -> 0 | G25: =COUNTIF(17_PPO1!$G$5:$G$12,"실패") -> 0 | H25: =COUNTIF(17_PPO1!$G$5:$G$12,"미측정") -> 0 | I25: =IFERROR((E25+F25+G25+H25)/D25,0) -> 0
A26: 18_PPO2 | B26: 18 | C26: PPO 튜닝: 시간·표본·실패 진단 | D26: 8 | E26: =COUNTIF(18_PPO2!$G$5:$G$12,"통과") -> 0 | F26: =COUNTIF(18_PPO2!$G$5:$G$12,"보류") -> 0 | G26: =COUNTIF(18_PPO2!$G$5:$G$12,"실패") -> 0 | H26: =COUNTIF(18_PPO2!$G$5:$G$12,"미측정") -> 0 | I26: =IFERROR((E26+F26+G26+H26)/D26,0) -> 0
A27: 21_학습비교 | B27: 21 | C27: 학습 환경·실험 비교표 | D27: 8 | E27: =COUNTIF(21_학습비교!$G$5:$G$12,"통과") -> 0 | F27: =COUNTIF(21_학습비교!$G$5:$G$12,"보류") -> 0 | G27: =COUNTIF(21_학습비교!$G$5:$G$12,"실패") -> 0 | H27: =COUNTIF(21_학습비교!$G$5:$G$12,"미측정") -> 0 | I27: =IFERROR((E27+F27+G27+H27)/D27,0) -> 0
A28: 22_경로예측 | B28: 22 | C28: 경로 예측: 미리 보는 거리를 조정 | D28: 4 | E28: =COUNTIF(22_경로예측!$G$5:$G$8,"통과") -> 0 | F28: =COUNTIF(22_경로예측!$G$5:$G$8,"보류") -> 0 | G28: =COUNTIF(22_경로예측!$G$5:$G$8,"실패") -> 0 | H28: =COUNTIF(22_경로예측!$G$5:$G$8,"미측정") -> 0 | I28: =IFERROR((E28+F28+G28+H28)/D28,0) -> 0
A29: 23_빠르고안정 | B29: 23 | C29: 보상 설계: 빠르면서 안정적인 주행 | D29: 4 | E29: =COUNTIF(23_빠르고안정!$G$5:$G$8,"통과") -> 0 | F29: =COUNTIF(23_빠르고안정!$G$5:$G$8,"보류") -> 0 | G29: =COUNTIF(23_빠르고안정!$G$5:$G$8,"실패") -> 0 | H29: =COUNTIF(23_빠르고안정!$G$5:$G$8,"미측정") -> 0 | I29: =IFERROR((E29+F29+G29+H29)/D29,0) -> 0
A30: 24_팔카메라보상 | B30: 24 | C30: 팔 카메라: 보상 설계 사례 | D30: 8 | E30: =COUNTIF(24_팔카메라보상!$G$5:$G$12,"통과") -> 0 | F30: =COUNTIF(24_팔카메라보상!$G$5:$G$12,"보류") -> 0 | G30: =COUNTIF(24_팔카메라보상!$G$5:$G$12,"실패") -> 0 | H30: =COUNTIF(24_팔카메라보상!$G$5:$G$12,"미측정") -> 0 | I30: =IFERROR((E30+F30+G30+H30)/D30,0) -> 0
A31: 25_팔카메라PPO | B31: 25 | C31: 팔 카메라: PPO 설정과 조정 사례 | D31: 8 | E31: =COUNTIF(25_팔카메라PPO!$G$5:$G$12,"통과") -> 0 | F31: =COUNTIF(25_팔카메라PPO!$G$5:$G$12,"보류") -> 0 | G31: =COUNTIF(25_팔카메라PPO!$G$5:$G$12,"실패") -> 0 | H31: =COUNTIF(25_팔카메라PPO!$G$5:$G$12,"미측정") -> 0 | I31: =IFERROR((E31+F31+G31+H31)/D31,0) -> 0
A32: 26_팔회전범위 | B32: 26 | C32: 팔 회전 범위: 근거와 적용 범위 | D32: 4 | E32: =COUNTIF(26_팔회전범위!$G$5:$G$8,"통과") -> 0 | F32: =COUNTIF(26_팔회전범위!$G$5:$G$8,"보류") -> 0 | G32: =COUNTIF(26_팔회전범위!$G$5:$G$8,"실패") -> 0 | H32: =COUNTIF(26_팔회전범위!$G$5:$G$8,"미측정") -> 0 | I32: =IFERROR((E32+F32+G32+H32)/D32,0) -> 0
A33: 32_cuVSLAM설정 | B33: 32 | C33: cuVSLAM: 최종 RGBD 설정과 토픽 | D33: 13 | E33: =COUNTIF(32_cuVSLAM설정!$E$5:$E$17,"통과") -> 0 | F33: =COUNTIF(32_cuVSLAM설정!$E$5:$E$17,"보류") -> 0 | G33: =COUNTIF(32_cuVSLAM설정!$E$5:$E$17,"실패") -> 0 | H33: =COUNTIF(32_cuVSLAM설정!$E$5:$E$17,"미측정") -> 0 | I33: =IFERROR((E33+F33+G33+H33)/D33,0) -> 0
A34: 33_cuVSLAM조정 | B34: 33 | C34: cuVSLAM: 조정과 수정의 구분 | D34: 4 | E34: =COUNTIF(33_cuVSLAM조정!$G$5:$G$8,"통과") -> 0 | F34: =COUNTIF(33_cuVSLAM조정!$G$5:$G$8,"보류") -> 0 | G34: =COUNTIF(33_cuVSLAM조정!$G$5:$G$8,"실패") -> 0 | H34: =COUNTIF(33_cuVSLAM조정!$G$5:$G$8,"미측정") -> 0 | I34: =IFERROR((E34+F34+G34+H34)/D34,0) -> 0
A35: 35_센서입력 | B35: 35 | C35: 센서 입력: 엔코더·카메라·두 OpenCR | D35: 8 | E35: =COUNTIF(35_센서입력!$G$5:$G$12,"통과") -> 0 | F35: =COUNTIF(35_센서입력!$G$5:$G$12,"보류") -> 0 | G35: =COUNTIF(35_센서입력!$G$5:$G$12,"실패") -> 0 | H35: =COUNTIF(35_센서입력!$G$5:$G$12,"미측정") -> 0 | I35: =IFERROR((E35+F35+G35+H35)/D35,0) -> 0
A36: 37_EKF_AMCL | B36: 37 | C36: 위치추정: EKF 융합과 Nav2 AMCL | D36: 8 | E36: =COUNTIF(37_EKF_AMCL!$G$5:$G$12,"통과") -> 0 | F36: =COUNTIF(37_EKF_AMCL!$G$5:$G$12,"보류") -> 0 | G36: =COUNTIF(37_EKF_AMCL!$G$5:$G$12,"실패") -> 0 | H36: =COUNTIF(37_EKF_AMCL!$G$5:$G$12,"미측정") -> 0 | I36: =IFERROR((E36+F36+G36+H36)/D36,0) -> 0
A37: 39_엔코더 | B37: 39 | C37: 엔코더 사례: 각도 래핑과 역회전 오류 | D37: 4 | E37: =COUNTIF(39_엔코더!$G$5:$G$8,"통과") -> 0 | F37: =COUNTIF(39_엔코더!$G$5:$G$8,"보류") -> 0 | G37: =COUNTIF(39_엔코더!$G$5:$G$8,"실패") -> 0 | H37: =COUNTIF(39_엔코더!$G$5:$G$8,"미측정") -> 0 | I37: =IFERROR((E37+F37+G37+H37)/D37,0) -> 0
A38: 42_Nav2통로 | B38: 42 | C38: Nav2: 통로·속도·도착 조정 | D38: 4 | E38: =COUNTIF(42_Nav2통로!$G$5:$G$8,"통과") -> 0 | F38: =COUNTIF(42_Nav2통로!$G$5:$G$8,"보류") -> 0 | G38: =COUNTIF(42_Nav2통로!$G$5:$G$8,"실패") -> 0 | H38: =COUNTIF(42_Nav2통로!$G$5:$G$8,"미측정") -> 0 | I38: =IFERROR((E38+F38+G38+H38)/D38,0) -> 0
A39: 43_Nav2_MPPI | B39: 43 | C39: Nav2: MPPI 파라미터를 바꿀 때 | D39: 4 | E39: =COUNTIF(43_Nav2_MPPI!$G$5:$G$8,"통과") -> 0 | F39: =COUNTIF(43_Nav2_MPPI!$G$5:$G$8,"보류") -> 0 | G39: =COUNTIF(43_Nav2_MPPI!$G$5:$G$8,"실패") -> 0 | H39: =COUNTIF(43_Nav2_MPPI!$G$5:$G$8,"미측정") -> 0 | I39: =IFERROR((E39+F39+G39+H39)/D39,0) -> 0
A40: 45_스워브모듈 | B40: 45 | C40: 스워브: 모듈 정의와 역기구학 | D40: 8 | E40: =COUNTIF(45_스워브모듈!$G$5:$G$12,"통과") -> 0 | F40: =COUNTIF(45_스워브모듈!$G$5:$G$12,"보류") -> 0 | G40: =COUNTIF(45_스워브모듈!$G$5:$G$12,"실패") -> 0 | H40: =COUNTIF(45_스워브모듈!$G$5:$G$12,"미측정") -> 0 | I40: =IFERROR((E40+F40+G40+H40)/D40,0) -> 0
A41: 46_스워브구동기 | B41: 46 | C41: Isaac Lab: 스워브 구동기·관측·시간 | D41: 8 | E41: =COUNTIF(46_스워브구동기!$G$5:$G$12,"통과") -> 0 | F41: =COUNTIF(46_스워브구동기!$G$5:$G$12,"보류") -> 0 | G41: =COUNTIF(46_스워브구동기!$G$5:$G$12,"실패") -> 0 | H41: =COUNTIF(46_스워브구동기!$G$5:$G$12,"미측정") -> 0 | I41: =IFERROR((E41+F41+G41+H41)/D41,0) -> 0
A42: 47_스워브반전 | B42: 47 | C42: 스워브: 조향 반전과 증상별 수정 | D42: 8 | E42: =COUNTIF(47_스워브반전!$G$5:$G$12,"통과") -> 0 | F42: =COUNTIF(47_스워브반전!$G$5:$G$12,"보류") -> 0 | G42: =COUNTIF(47_스워브반전!$G$5:$G$12,"실패") -> 0 | H42: =COUNTIF(47_스워브반전!$G$5:$G$12,"미측정") -> 0 | I42: =IFERROR((E42+F42+G42+H42)/D42,0) -> 0
A43: 48_스워브Nav2 | B43: 48 | C43: 부록: 스워브와 Nav2 연결 | D43: 4 | E43: =COUNTIF(48_스워브Nav2!$G$5:$G$8,"통과") -> 0 | F43: =COUNTIF(48_스워브Nav2!$G$5:$G$8,"보류") -> 0 | G43: =COUNTIF(48_스워브Nav2!$G$5:$G$8,"실패") -> 0 | H43: =COUNTIF(48_스워브Nav2!$G$5:$G$8,"미측정") -> 0 | I43: =IFERROR((E43+F43+G43+H43)/D43,0) -> 0
A44: 49_동역학조향 | B44: 49 | C44: 동역학·조향: 문제와 수정 사례 | D44: 8 | E44: =COUNTIF(49_동역학조향!$G$5:$G$12,"통과") -> 0 | F44: =COUNTIF(49_동역학조향!$G$5:$G$12,"보류") -> 0 | G44: =COUNTIF(49_동역학조향!$G$5:$G$12,"실패") -> 0 | H44: =COUNTIF(49_동역학조향!$G$5:$G$12,"미측정") -> 0 | I44: =IFERROR((E44+F44+G44+H44)/D44,0) -> 0
...

Sheet 02_완료기준
A1: [슬라이드 2] 실습 목표·완료 기준
A2: 출처: 선생님 공유 슬라이드 「팀별 로봇 미로 주행 — 보상 설계·cuVSLAM·Nav2 실습」 · 회색 = 슬라이드 예시(M38 시연), 노란색 = 우리 팀이 관찰해서 채울 칸
A4: 완료 기준 | B4: 목표값 | C4: 단위 | D4: 우리 측정값 | E4: 판정 | F4: 근거(로그·영상·파일) | G4: 메모
A5: 실제 목표 오차 (미만) | B5: 0.1 | C5: m | E5: =IF(D5="","",IF(D5<B5,"통과","실패"))
A6: 차체 최고 속도 (이하) | B6: 0.951 | C6: m/s | E6: =IF(D6="","",IF(D6<=B6,"통과","실패"))
A7: 비바퀴 접촉 (이하) | B7: 0.5 | C7: N | E7: =IF(D7="","",IF(D7<=B7,"통과","실패"))
A8: 센서 누락 시 정지·복구 확인 | C8: -
A9: 로그·GUI 녹화·설정 파일 제출 | C9: -
A10: 실물 미측정 가정을 따로 적기 | C10: -
A12: 판정: 숫자 기준 3개(5~7행)는 측정값을 넣으면 자동으로 통과/실패, 8~10행은 목록에서 직접 고르기

Sheet 07_팀별변경
A1: [슬라이드 7] 팀별 로봇: 그대로 복사하지 않을 값
A2: 출처: 선생님 공유 슬라이드 「팀별 로봇 미로 주행 — 보상 설계·cuVSLAM·Nav2 실습」 · 회색 = 슬라이드 예시(M38 시연), 노란색 = 우리 팀이 관찰해서 채울 칸
A4: 설정 | B4: M38 시뮬 예시 | C4: 팀별 변경 | D4: 검증 | E4: 우리 로봇 설정값 | F4: 관찰·측정 결과 | G4: 판정 | H4: 근거(로그·영상·파일) | I4: 담당 | J4: 날짜 | K4: 메모
A5: 기구학 | B5: 반경 0.030687 m / 기어 4 | C5: URDF 축·반경·모듈 위치 | D5: 직진·횡이동·회전 시험
A6: 동역학 | B6: 질량·토크·관성은 가정 포함 | C6: 실측 질량·COM·모터 한계 | D6: 전류·정지거리·슬립
A7: 카메라·IMU | B7: 가상 stereo / CAD 장착값 | C7: intrinsic·TF·시각·noise | D7: 정지·회전·가속 기록
A8: 정책 배포 | B8: 24개 관측 / 2개 행동 | C8: 정규화·단위·제약 일치 | D8: 실제 영상 폐루프 평가

Sheet 11_보상1
A1: [슬라이드 11] 보상 사례: 진행·시간·목표 도착
A2: 출처: 선생님 공유 슬라이드 「팀별 로봇 미로 주행 — 보상 설계·cuVSLAM·Nav2 실습」 · 회색 = 슬라이드 예시(M38 시연), 노란색 = 우리 팀이 관찰해서 채울 칸
A4: 항목 | B4: 기준·해석 | C4: 조정 사례 | D4: 확인할 결과 | E4: 우리 로봇 설정값 | F4: 관찰·측정 결과 | G4: 판정 | H4: 근거(로그·영상·파일) | I4: 담당 | J4: 날짜 | K4: 메모
A5: 목표로 접근 | B5: 진행 계수 4 | C5: 2·4·8 비교 | D5: 목표 거리 감소
A6: 제자리 정지 | B6: 시간 비용 0.02 | C6: 0.01·0.02·0.04 | D6: 정체·충돌 함께
A7: 과한 행동 억제 | B7: 행동 비용 0.01 | C7: 0.005·0.01·0.02 | D7: 도착 시간·포화
A8: 목표 도착 | B8: 도달 보너스 2 | C8: 1·2·4 비교 | D8: 완주율·반복 수령
A9: 도착 직전 진동 | B9: 반경 0.12 m | C9: 0.08·0.12·0.16 | D9: 오차·도달 시간
A10: 목표 지나쳐 성공 | B10: 거리만 사용 | C10: 속도 조건도 추가 | D10: 정지 후 도착
A11: 목표 보너스 반복 | B11: 매 step +2 | C11: 최초 도달·종료 | D11: 보너스 횟수
A12: 넘어져 빨리 끝냄 | B12: 실패 비용 없음 | C12: 실패 비용·모델 점검 | D12: 실패율·return

Sheet 12_보상2
A1: [슬라이드 12] 보상 사례: 항의 크기·관측·악용
A2: 출처: 선생님 공유 슬라이드 「팀별 로봇 미로 주행 — 보상 설계·cuVSLAM·Nav2 실습」 · 회색 = 슬라이드 예시(M38 시연), 노란색 = 우리 팀이 관찰해서 채울 칸
A4: 항목 | B4: 기준·해석 | C4: 조정 사례 | D4: 확인할 결과 | E4: 우리 로봇 설정값 | F4: 관찰·측정 결과 | G4: 판정 | H4: 근거(로그·영상·파일) | I4: 담당 | J4: 날짜 | K4: 메모
A5: 1 cm 전진 | B5: dt=1/15초 | C5: 진행 항 +0.60 | D5: 방향·단위 검산
A6: 1 cm 후퇴 | B6: 같은 목표 | C6: 진행 항 −0.60 | D6: 후진을 항상 벌하지 않기
A7: 행동 두 축 최대 | B7: 각 축 |a|≤1 | C7: 행동 항 −0.02 | D7: 진행 항과 비율
A8: 8초 정지 | B8: 120 step | C8: 시간 합 −2.4 | D8: 자살 종료 유인
A9: 접촉 벌점만 추가 | B9: 벽 입력 없음 | C9: 거리·접촉 관측 추가 | D9: 상태 구분 여부
A10: 한 방향만 성공 | B10: 전방 목표만 학습 | C10: 양방향·여러 시작점 | D10: 시작점별 성공률
A11: 보상만 급상승 | B11: reset 거리 튐 | C11: 기준 거리 재설정 | D11: reset 직전·직후
A12: Sim만 잘 움직임 | B12: 정답 pose 학습 | C12: 노이즈·지연 단계화 | D12: 추정 pose 평가

Sheet 13_보상3
A1: [슬라이드 13] 보상 사례: 충돌·코너·우회
A2: 출처: 선생님 공유 슬라이드 「팀별 로봇 미로 주행 — 보상 설계·cuVSLAM·Nav2 실습」 · 회색 = 슬라이드 예시(M38 시연), 노란색 = 우리 팀이 관찰해서 채울 칸
A4: 상황 | B4: 설계 기준 | C4: 조정 사례 | D4: 확인할 결과 | E4: 우리 로봇 설정값 | F4: 관찰·측정 결과 | G4: 판정 | H4: 근거(로그·영상·파일) | I4: 담당 | J4: 날짜 | K4: 메모
A5: 벽에 계속 밀기 | B5: 충돌 이벤트 비용 | C5: 작은 값부터 증가 | D5: 접촉률·정지율
A6: 벽에 너무 근접 | B6: 거리 여유 비용 | C6: 안전거리 안에서만 | D6: 최소 외곽 거리
A7: 바닥 접촉 벌점 | B7: 접촉 필터 오류 | C7: 벽·차체만 구분 | D7: 정지 중 감점 여부
A8: 좁은 통로 회피 | B8: 과한 안전거리 | C8: 통로 반폭 이하 검토 | D8: 통과 가능성
A9: 직선 거리만 감소 | B9: 벽 뒤 목표 | C9: 경로 진행률 사용 | D9: 벽 관통 지름길
A10: 코너에서 정체 | B10: 먼 lookahead | C10: 6점 → 3점 비교 | D10: 코너 여유·진동
A11: 막다른 길 탈출 | B11: 후진을 일괄 벌점 | C11: 목표 진행으로 보상 | D11: 후진 회복 성공
A12: 우회 중 거리 증가 | B12: 직선 거리 페널티 | C12: 경로 잔여길이 고려 | D12: 우회 경로 선택

Sheet 14_보상4
A1: [슬라이드 14] 보상 사례: 진동·정체·설계 오류
A2: 출처: 선생님 공유 슬라이드 「팀별 로봇 미로 주행 — 보상 설계·cuVSLAM·Nav2 실습」 · 회색 = 슬라이드 예시(M38 시연), 노란색 = 우리 팀이 관찰해서 채울 칸
A4: 증상 / 항목 | B4: 기준·원인 | C4: 조정 / 확인 | D4: 판단 기준 | E4: 우리 로봇 설정값 | F4: 관찰·측정 결과 | G4: 판정 | H4: 근거(로그·영상·파일) | I4: 담당 | J4: 날짜 | K4: 메모
A5: 좌우 명령 진동 | B5: 행동 변화 비용 | C5: ‖a−a_prev‖² 추가 | D5: 전환 횟수·지연
A6: 조향각 반복 반전 | B6: ±90° 분기 | C6: 구동 분기부터 수정 | D6: 바퀴 부호·정체
A7: 급가속·미끄러짐 | B7: 가속도 비용 | C7: 낮은 계수부터 | D7: 미끄럼·주행 시간
A8: 전복·지면 이탈 | B8: 기울기 + 실패 | C8: 실패 종료·비용 | D8: 안정 높이·완주
A9: 정지 상태 유지 | B9: 진행·시간 항 불균형 | C9: 항별 평균 크기 비교 | D9: 정지 보상 악용
A10: 벽에 밀착 | B10: 접촉·거리 관측 누락 | C10: 거리·접촉 항 추가 | D10: 접촉 감소
A11: 목표 주변 진동 | B11: 종료·감속 조건 불일치 | C11: 속도·거리 함께 판정 | D11: 안정된 도착
A12: 리셋 보상 급증 | B12: 이전 거리 미초기화 | C12: reset 상태 함께 초기화 | D12: 보상 spike 제거

Sheet 17_PPO1
A1: [슬라이드 17] PPO 튜닝: 업데이트·탐색·가치함수
A2: 출처: 선생님 공유 슬라이드 「팀별 로봇 미로 주행 — 보상 설계·cuVSLAM·Nav2 실습」 · 회색 = 슬라이드 예시(M38 시연), 노란색 = 우리 팀이 관찰해서 채울 칸
A4: 상황 / 항목 | B4: 기준 / 예시 | C4: 조정 방향 | D4: 확인할 결과 | E4: 우리 로봇 설정값 | F4: 관찰·측정 결과 | G4: 판정 | H4: 근거(로그·영상·파일) | I4: 담당 | J4: 날짜 | K4: 메모
A5: 학습률 | B5: 3e−4 | C5: 불안정: 1e−4 비교 | D5: KL·성능 급락
A6: clip epsilon | B6: 0.2 | C6: 큰 갱신: 0.1 비교 | D6: clip fraction
A7: update epoch | B7: 4 | C7: 과적합: 2로 감소 | D7: KL·새 평가 성능
A8: gradient norm | B8: 1.0 | C8: 폭발: 원인 먼저 확인 | D8: gradient·NaN
A9: entropy 계수 | B9: 0.005 | C9: 탐색 부족: 0.01 비교 | D9: 행동 std·충돌
A10: 초기 log_std | B10: −0.7 | C10: 포화 많음: −1 비교 | D10: clamp 비율
A11: value loss 계수 | B11: 0.5 | C11: 가치 오차 먼저 분석 | D11: value loss·설명력
A12: 관측 정규화 | B12: 목표 clamp ±1 | C12: 분포·단위 먼저 확인 | D12: 입력 포화 비율

Sheet 18_PPO2
A1: [슬라이드 18] PPO 튜닝: 시간·표본·실패 진단
A2: 출처: 선생님 공유 슬라이드 「팀별 로봇 미로 주행 — 보상 설계·cuVSLAM·Nav2 실습」 · 회색 = 슬라이드 예시(M38 시연), 노란색 = 우리 팀이 관찰해서 채울 칸
A4: 상황 / 항목 | B4: 기준 / 예시 | C4: 조정 방향 | D4: 확인할 결과 | E4: 우리 로봇 설정값 | F4: 관찰·측정 결과 | G4: 판정 | H4: 근거(로그·영상·파일) | I4: 담당 | J4: 날짜 | K4: 메모
A5: gamma | B5: 0.99 | C5: 먼 성과: 0.995 비교 | D5: 지연 보상·분산
A6: GAE lambda | B6: 0.95 | C6: 분산 큼: 0.9 비교 | D6: advantage 분산
A7: rollout 길이 | B7: 64 step | C7: 긴 의존성: 128 비교 | D7: 메모리·표본 수
A8: minibatch | B8: 256 | C8: 총 표본 수와 맞춤 | D8: 업데이트 횟수
A9: timeout bootstrap | B9: 현재 terminal 처리 | C9: truncated 별도 처리 | D9: value 편향
A10: 보상 스케일 변경 | B10: value target도 변경 | C10: 학습 안정성 재확인 | D10: value loss·KL
A11: 이어 학습 | B11: optimizer 상태 복원 | C11: 설정 변경 반영 확인 | D11: 실제 lr 출력
A12: 좋은 정책 선택 | B12: 마지막 파일 아님 | C12: 고정 평가로 선택 | D12: 완주·충돌·시간

Sheet 21_학습비교
A1: [슬라이드 21] 학습 환경·실험 비교표
A2: 출처: 선생님 공유 슬라이드 「팀별 로봇 미로 주행 — 보상 설계·cuVSLAM·Nav2 실습」 · 회색 = 슬라이드 예시(M38 시연), 노란색 = 우리 팀이 관찰해서 채울 칸
A4: 상황 / 항목 | B4: 기준 / 예시 | C4: 조정 방향 | D4: 확인할 결과 | E4: 우리 로봇 설정값 | F4: 관찰·측정 결과 | G4: 판정 | H4: 근거(로그·영상·파일) | I4: 담당 | J4: 날짜 | K4: 메모
A5: 학습 목표 거리 | B5: 경로 ±12점 | C5: 실패 많음: ±6점 | D5: 도달률·방향별 차이
A6: 시작 위치 오차 | B6: XY ±0.05 m | C6: 안정 후 단계 확대 | D6: 초기 위치의 벽 침범
A7: episode 길이 | B7: 8초 | C7: 도달 가능한 시간 확보 | D7: timeout 비중
A8: 병렬 환경 | B8: 8개 | C8: 메모리 보며 16개 | D8: 표본/s·재현성
A9: A: 기준 | B9: 진행 4 / 시간 .02 | C9: 나머지 고정 | D9: 성공·충돌·시간
A10: B: 진행만 변경 | B10: 진행 2 | C10: A와 같은 seed | D10: 정체 개선 여부
A11: C: 시간만 변경 | B11: 시간 .01 | C11: A에서 다시 시작 | D11: 충돌 감소 여부
A12: D: 최종 후보 | B12: 우수 설정 하나 | C12: 새 시작점·seed | D12: 일반화 성능

Sheet 22_경로예측
A1: [슬라이드 22] 경로 예측: 미리 보는 거리를 조정
A2: 출처: 선생님 공유 슬라이드 「팀별 로봇 미로 주행 — 보상 설계·cuVSLAM·Nav2 실습」 · 회색 = 슬라이드 예시(M38 시연), 노란색 = 우리 팀이 관찰해서 채울 칸
A4: 상황 | B4: 예측·조정 방법 | C4: 수치 예시 | D4: 검증 기준 | E4: 우리 로봇 설정값 | F4: 관찰·측정 결과 | G4: 판정 | H4: 근거(로그·영상·파일) | I4: 담당 | J4: 날짜 | K4: 메모
A5: 빠른 직선 뒤 코너 | B5: 팔 회전시간만큼 앞보기 | C5: 90°÷0.5 ≈ 3.14초 | D5: 코너 진입 전 관측
A6: FOV 안에 방향 존재 | B6: 필요 회전각에서 FOV 고려 | C6: 35° 이내면 전방 관측 | D6: 가림·특징점은 별도
A7: S자 코너가 연속 | B7: 다음 한 점만 보지 않기 | C7: 경로 방향열·곡률 확장 | D7: 팔 왕복·추적 끊김
A8: 급정지 반복 | B8: preview·제동 여유 공동 조정 | C8: 시야 먼저 / 감속 병행 | D8: 정지율과 완주 시간

Sheet 23_빠르고안정
A1: [슬라이드 23] 보상 설계: 빠르면서 안정적인 주행
A2: 출처: 선생님 공유 슬라이드 「팀별 로봇 미로 주행 — 보상 설계·cuVSLAM·Nav2 실습」 · 회색 = 슬라이드 예시(M38 시연), 노란색 = 우리 팀이 관찰해서 채울 칸
A4: 증상 | B4: 현재 보상 / 비용 | C4: 비교할 변경 사례 | D4: 함께 볼 측정값 | E4: 우리 로봇 설정값 | F4: 관찰·측정 결과 | G4: 판정 | H4: 근거(로그·영상·파일) | I4: 담당 | J4: 날짜 | K4: 메모
A5: 가속 후 기울어짐 | B5: 기울기 비용 계수 2 | C5: 2→4 / IMU 입력 유지 | D5: 최대 경사·완주 시간
A6: 팔이 코너를 늦게 봄 | B6: yaw 오차감소 0.25 | C6: 0.25→0.5 단독 비교 | D6: 미관측 시간·정지율
A7: 가속 명령이 진동 | B7: Δ가속 행동 비용 0.01 | C7: 0.01→0.03 비교 | D7: jerk·주행 시간
A8: 빠르지만 충돌 | B8: 실패 −5 / 진행 8Δs | C8: 실패 −10부터 비교 | D8: 충돌률 먼저, 이후 속도

Sheet 24_팔카메라보상
A1: [슬라이드 24] 팔 카메라: 보상 설계 사례
A2: 출처: 선생님 공유 슬라이드 「팀별 로봇 미로 주행 — 보상 설계·cuVSLAM·Nav2 실습」 · 회색 = 슬라이드 예시(M38 시연), 노란색 = 우리 팀이 관찰해서 채울 칸
A4: 상황 / 항목 | B4: 설계 / 시작점 | C4: 조정·구현 방법 | D4: 평가할 결과 | E4: 우리 로봇 설정값 | F4: 관찰·측정 결과 | G4: 판정 | H4: 근거(로그·영상·파일) | I4: 담당 | J4: 날짜 | K4: 메모
A5: 시야 확보 후 진행 | B5: 진행량에 가중치 | C5: 이동 가능할 때 지급 | D5: 멈춤 악용 방지
A6: 카메라 방향 정렬 | B6: yaw 오차 감소 | C6: 관측 품질과 결합 | D6: 정렬 시간·오차
A7: 시야 확인 보상 | B7: ready 상태 | C7: 지속 지급 금지 | D7: 회전만 반복 방지
A8: 시야 없는 이동 | B8: 속도 × 미관측 | C8: 강한 감점 | D8: 실제 가시성 확인
A9: 불필요한 회전 | B9: yaw 변화량 | C9: 가중치 단계 증가 | D9: 정렬·정체 비교
A10: 추적 실패 | B10: 실패 이벤트 | C10: 복구와 종료 분리 | D10: 재획득 시간
A11: 관절·충돌 한계 | B11: 제한 위반·접촉 | C11: 즉시 차단·감점 | D11: 안전한 자세
A12: 목표·종료 | B12: 도착 +5 / 실패 −5 | C12: 중복 지급 방지 | D12: 도착 판정 일치

Sheet 25_팔카메라PPO
A1: [슬라이드 25] 팔 카메라: PPO 설정과 조정 사례
A2: 출처: 선생님 공유 슬라이드 「팀별 로봇 미로 주행 — 보상 설계·cuVSLAM·Nav2 실습」 · 회색 = 슬라이드 예시(M38 시연), 노란색 = 우리 팀이 관찰해서 채울 칸
A4: 항목 / 상황 | B4: 실제 설정 / 결과 | C4: 조정·구현 방법 | D4: 해석 / 주의점 | E4: 우리 로봇 설정값 | F4: 관찰·측정 결과 | G4: 판정 | H4: 근거(로그·영상·파일) | I4: 담당 | J4: 날짜 | K4: 메모
A5: 학습률 / clip | B5: 3e−4 / 0.2 | C5: 진동·KL 증가면 lr↓ | D5: 다른 항은 고정 비교
A6: gamma / lambda | B6: 0.99 / 0.95 | C6: 긴 대기면 .995 비교 | D6: 이번 결과는 .99
A7: rollout / batch | B7: 128×16 = 2,048 | C7: minibatch256 / epoch4 | D7: 업데이트당 32 batch
A8: 손실 / 신경망 | B8: value0.5 / entropy0.005 | C8: 64–64 Tanh / grad clip1 | D8: std는 학습됨
A9: 정렬을 기다리지 못함 | B9: episode 8 → 16초 | C9: 정렬 소요시간부터 측정 | D9: timeout 비율
A10: 팔이 급하게 흔들림 | B10: 팔 action 범위 축소 | C10: lr 3e−4 → 1e−4 비교 | D10: 속도·KL·추적률
A11: 긴 대기 뒤 성과 | B11: rollout 64 → 128 | C11: gamma .99 → .995 별도 | D11: advantage·value 오차
A12: 안전 정지만 학습 | B12: 단계 1부터 재학습 | C12: ready 반복보상 제거 | D12: 정렬률·주행 성공률

Sheet 26_팔회전범위
A1: [슬라이드 26] 팔 회전 범위: 근거와 적용 범위
A2: 출처: 선생님 공유 슬라이드 「팀별 로봇 미로 주행 — 보상 설계·cuVSLAM·Nav2 실습」 · 회색 = 슬라이드 예시(M38 시연), 노란색 = 우리 팀이 관찰해서 채울 칸
A4: 항목 / 상황 | B4: 실제 설정 / 결과 | C4: 조정·구현 방법 | D4: 해석 / 주의점 | E4: 우리 로봇 설정값 | F4: 관찰·측정 결과 | G4: 판정 | H4: 근거(로그·영상·파일) | I4: 담당 | J4: 날짜 | K4: 메모
A5: 기존 ±0.35 rad | B5: 약 ±20° 시험 창 | C5: 기계 한계로 해석 금지 | D5: CAD 검증용 임시값
A6: 팔 기저 yaw | B6: 공식 OMX: ±180° | C6: 시연 자산 joint1 적용 | D6: 배선 한계는 별도
A7: 나머지 팔 4축 | B7: 이번 학습에서는 0 고정 | C7: 사용자 정의 wrist 포함 | D7: 순정 범위 복사 금지
A8: CAD yaw 검사 | B8: 361자세 / 검출 간섭 0 | C8: 베이스↔팔 link2~5 | D8: 배선·동적 충돌 제외

Sheet 32_cuVSLAM설정
A1: [슬라이드 32] cuVSLAM: 최종 RGBD 설정과 토픽
A2: 출처: 선생님 공유 슬라이드 「팀별 로봇 미로 주행 — 보상 설계·cuVSLAM·Nav2 실습」 · 회색 = 슬라이드 예시(M38 시연), 노란색 = 우리 팀이 관찰해서 채울 칸
A4: 설정 / 점검 항목 | B4: 슬라이드 예시 값 | C4: 우리 값 | D4: 확인 결과 | E4: 판정 | F4: 근거(로그·명령 출력) | G4: 메모
A5: tracking_mode | B5: 2 (RGBD)
A6: rectified_images | B6: true
A7: depth_scale_factor | B7: 1000
A8: depth_enable_stereo_tracking | B8: true
A9: enable_imu_fusion | B9: false
A10: base_frame | B10: camera_rig
A11: 입력 토픽 | B11: 좌우 RGB + CameraInfo + depth
A12: 깊이 토픽 | B12: /arm_stereo/left/depth
A13: 깊이 형식 | B13: 16UC1, mm 단위
A14: 팔 FK 시각 | B14: 영상과 같은 시각의 팔 FK 사용
A15: 좌우 영상 | B15: 좌우 동기·intrinsic·baseline 확인
A16: 노드 점검 | B16: ros2 node info /visual_slam
A17: TF·clock | B17: 발행자 중복 제거

Sheet 33_cuVSLAM조정
A1: [슬라이드 33] cuVSLAM: 조정과 수정의 구분
A2: 출처: 선생님 공유 슬라이드 「팀별 로봇 미로 주행 — 보상 설계·cuVSLAM·Nav2 실습」 · 회색 = 슬라이드 예시(M38 시연), 노란색 = 우리 팀이 관찰해서 채울 칸
A4: 상황 / 항목 | B4: 기준 / 예시 | C4: 조정 방향 | D4: 확인할 결과 | E4: 우리 로봇 설정값 | F4: 관찰·측정 결과 | G4: 판정 | H4: 근거(로그·영상·파일) | I4: 담당 | J4: 날짜 | K4: 메모
A5: 영상이 뒤틀림 | B5: K·D·R·P | C5: 보정값 수정 | D5: 수평 에피폴라
A6: 추적이 끊김 | B6: 노출·무늬·동기 | C6: 입력 품질부터 | D6: 추적률·지연
A7: 위치 축이 틀림 | B7: optical TF | C7: 축·외부보정 수정 | D7: 직진·회전 방향
A8: IMU를 추가함 | B8: fusion=false | C8: 시간·외부보정 후 on | D8: 드리프트·안정성

Sheet 35_센서입력
A1: [슬라이드 35] 센서 입력: 엔코더·카메라·두 OpenCR
A2: 출처: 선생님 공유 슬라이드 「팀별 로봇 미로 주행 — 보상 설계·cuVSLAM·Nav2 실습」 · 회색 = 슬라이드 예시(M38 시연), 노란색 = 우리 팀이 관찰해서 채울 칸
A4: 입력 / 항목 | B4: 구성·공식 설정 | C4: 사용 방법 | D4: 확인 기준 | E4: 우리 로봇 설정값 | F4: 관찰·측정 결과 | G4: 판정 | H4: 근거(로그·영상·파일) | I4: 담당 | J4: 날짜 | K4: 메모
A5: 이중 IMU | B5: PhysX → ADC → ROS | C5: 200 Hz / 보드 축 | D5: 레버암 포함
A6: 엔코더 13축 | B6: unwrap → count | C6: 200 Hz / 30 ms 창 | D6: 래핑·진동 제거
A7: 팔 스테레오 | B7: RGB·깊이·FK | C7: 동일 촬영 시각 | D7: 최신 FK 혼용 금지
A8: 비동기 실행 | B8: CPU 물리·GPU 영상 | C8: clock 발행자 1개 | D8: 늦은 값 차단
A9: OpenCR 범위 | B9: ±2 g / ±2000°/s | C9: m/s² · rad/s | D9: aRes=8 g 금지
A10: 보드별 구분 | B10: imu 1 · imu 2 토픽 | C10: USB 포트 별도 | D10: 장치 ID 고정
A11: 통신 검사 | B11: 200 Hz 요청 | C11: CRC·순서·포화 | D11: USB 시각은 추정
A12: 검증 범위 | B12: core 1.5.3 컴파일 | C12: ROS+PTY 통과 | D12: 실물 플래시 미실행

Sheet 37_EKF_AMCL
A1: [슬라이드 37] 위치추정: EKF 융합과 Nav2 AMCL
A2: 출처: 선생님 공유 슬라이드 「팀별 로봇 미로 주행 — 보상 설계·cuVSLAM·Nav2 실습」 · 회색 = 슬라이드 예시(M38 시연), 노란색 = 우리 팀이 관찰해서 채울 칸
A4: 측정 / 설정 | B4: 현재 구성 | C4: 변경 / 제외 항목 | D4: 이유 / 확인 | E4: 우리 로봇 설정값 | F4: 관찰·측정 결과 | G4: 판정 | H4: 근거(로그·영상·파일) | I4: 담당 | J4: 날짜 | K4: 메모
A5: wheel odometry | B5: 차체 vx·vy | C5: 적분 위치 제외 | D5: 중복 융합 방지
A6: 이중 IMU | B6: 보정 yaw rate | C6: AHRS yaw 제외 | D6: 공통 축·시각
A7: VO + 팔 FK | B7: 위치 차분 → 속도 | C7: VO yaw 제외 | D7: 팔·차체 분리
A8: 평면 좌표 | B8: 초기 body 기준 | C8: 회전 후 투영 | D8: pitch만 0 금지
A9: AMCL 운동 모델 | B9: OmniMotionModel | C9: 차동 모델 금지 | D9: 횡이동 편향 검사
A10: scan 입력 | B10: 팔 깊이 / 1° bin | C10: 범위 0.23–5 m | D10: 미관측은 infinity
A11: 입자·갱신 | B11: 500–1500 입자 | C11: 이동 0.01 m | D11: 오차·CPU 비교
A12: TF 소유권 | B12: map→odom→base | C12: 발행 중복 제거 | D12: 영상 시각 조회

Sheet 39_엔코더
A1: [슬라이드 39] 엔코더 사례: 각도 래핑과 역회전 오류
A2: 출처: 선생님 공유 슬라이드 「팀별 로봇 미로 주행 — 보상 설계·cuVSLAM·Nav2 실습」 · 회색 = 슬라이드 예시(M38 시연), 노란색 = 우리 팀이 관찰해서 채울 칸
A4: 항목 | B4: 잘못된 처리 | C4: 현재 구현 | D4: 튜닝할 값 | E4: 우리 로봇 설정값 | F4: 관찰·측정 결과 | G4: 판정 | H4: 근거(로그·영상·파일) | I4: 담당 | J4: 날짜 | K4: 메모
A5: 관절 각도 래핑 | B5: 원시 각도를 곧바로 차분 | C5: 200 Hz에서 연속각 복원 | D5: 최대 속도 × 주기 < π
A6: 속도 추정 | B6: 5 ms 양자화 차분만 사용 | C6: 약 30 ms 차분창 | D6: 10 / 30 / 50 ms 비교
A7: 카운트·기어 | B7: 바퀴 count를 모터로 오인 | C7: 모터축 = 바퀴각 / 4 | D7: 실물 CPR·기어비로 교체
A8: 검증 | B8: 명령 속도만 확인 | C8: native 속도·카운트 비교 | D8: 래핑 때 spike가 없어야 함

Sheet 42_Nav2통로
A1: [슬라이드 42] Nav2: 통로·속도·도착 조정
A2: 출처: 선생님 공유 슬라이드 「팀별 로봇 미로 주행 — 보상 설계·cuVSLAM·Nav2 실습」 · 회색 = 슬라이드 예시(M38 시연), 노란색 = 우리 팀이 관찰해서 채울 칸
A4: 상황 / 항목 | B4: 기준 / 예시 | C4: 조정 방향 | D4: 확인할 결과 | E4: 우리 로봇 설정값 | F4: 관찰·측정 결과 | G4: 판정 | H4: 근거(로그·영상·파일) | I4: 담당 | J4: 날짜 | K4: 메모
A5: 좁은 통로 실패 | B5: footprint·padding | C5: 실제 외곽부터 수정 | D5: 실제 충돌 여유
A6: 벽 가까이 주행 | B6: inflation 설정 | C6: 비용 분포 점검 | D6: 여유 거리·통과
A7: 코너를 크게 벗어남 | B7: 속도·가속도 | C7: 우선 저속으로 | D7: 추종오차·제동거리
A8: 목표에서 진동 | B8: goal tolerance | C8: 센서 오차보다 여유 | D8: 정지·방향 오차

Sheet 43_Nav2_MPPI
A1: [슬라이드 43] Nav2: MPPI 파라미터를 바꿀 때
A2: 출처: 선생님 공유 슬라이드 「팀별 로봇 미로 주행 — 보상 설계·cuVSLAM·Nav2 실습」 · 회색 = 슬라이드 예시(M38 시연), 노란색 = 우리 팀이 관찰해서 채울 칸
A4: 상황 / 항목 | B4: 기준 / 예시 | C4: 조정 방향 | D4: 확인할 결과 | E4: 우리 로봇 설정값 | F4: 관찰·측정 결과 | G4: 판정 | H4: 근거(로그·영상·파일) | I4: 담당 | J4: 날짜 | K4: 메모
A5: motion_model | B5: 스워브: Omni | C5: 실제 구동 구조와 일치 | D5: 횡이동 동작 확인
A6: vx·vy·wz 제한 | B6: 구동기 실측값 | C6: 포화 시 한계 낮춤 | D6: 명령 대비 실제 속도
A7: model_dt·time_steps | B7: 예측 시간 결정 | C7: 제동·코너 길이 고려 | D7: 예측 궤적·연산시간
A8: batch_size·온도 | B8: 샘플·선택 민감도 | C8: 기본값에서 한 항씩 | D8: 지연·충돌·진동

Sheet 45_스워브모듈
A1: [슬라이드 45] 스워브: 모듈 정의와 역기구학
A2: 출처: 선생님 공유 슬라이드 「팀별 로봇 미로 주행 — 보상 설계·cuVSLAM·Nav2 실습」 · 회색 = 슬라이드 예시(M38 시연), 노란색 = 우리 팀이 관찰해서 채울 칸
A4: 상황 / 항목 | B4: 기준 / 예시 | C4: 조정 방향 | D4: 확인할 결과 | E4: 우리 로봇 설정값 | F4: 관찰·측정 결과 | G4: 판정 | H4: 근거(로그·영상·파일) | I4: 담당 | J4: 날짜 | K4: 메모
A5: 모듈 위치 | B5: (x_i, y_i) | C5: base 기준 m | D5: 앞뒤·좌우 부호
A6: 바퀴 반경 | B6: 시연 0.030687 m | C6: 팀 USD 실측 | D6: 속도 환산·미끄럼
A7: 조향 영점 | B7: beta_i | C7: 관절 0의 굴림 방향 | D7: 전진 명령 테스트
A8: 관절 순서 | B8: 조향4 + 바퀴4 | C8: 이름으로 매핑 | D8: 동일 모듈 짝
A9: 모듈 X 속도 | B9: u_i = vx − wz·y_i | C9: body 좌표 사용 | D9: 순수 전진
A10: 모듈 Y 속도 | B10: v_i = vy + wz·x_i | C10: rad/s와 m 혼동 금지 | D10: 순수 횡이동
A11: 조향 목표 | B11: atan2(v_i,u_i)−beta_i | C11: 각도 wrap | D11: 제자리 회전
A12: 바퀴 각속도 | B12: sqrt(u²+v²) / r | C12: 회전 부호 적용 | D12: 모든 모듈 접선

Sheet 46_스워브구동기
A1: [슬라이드 46] Isaac Lab: 스워브 구동기·관측·시간
A2: 출처: 선생님 공유 슬라이드 「팀별 로봇 미로 주행 — 보상 설계·cuVSLAM·Nav2 실습」 · 회색 = 슬라이드 예시(M38 시연), 노란색 = 우리 팀이 관찰해서 채울 칸
A4: 상황 / 항목 | B4: 기준 / 예시 | C4: 조정 방향 | D4: 확인할 결과 | E4: 우리 로봇 설정값 | F4: 관찰·측정 결과 | G4: 판정 | H4: 근거(로그·영상·파일) | I4: 담당 | J4: 날짜 | K4: 메모
A5: steer 위치 제어 | B5: Kp 30 / Kd 3 예시 | C5: 진동 시 감쇠 ↑ | D5: 과도 응답
A6: wheel 속도 제어 | B6: Kp 0 / Kd 1 예시 | C6: 추종 오차·진동 | D6: 속도·슬립
A7: effort limit | B7: 모터 1 Nm 가정 | C7: 정격으로 교체 | D7: 발열·전류
A8: articulation root | B8: base_link | C8: 원본·충돌 검사 | D8: 부유·초기 자세
A9: 시간 설정 | B9: 최종 물리 200 Hz | C9: decimation 13 | D9: 정책 15.38 Hz
A10: 행동 | B10: 가감속·팔 yaw | C10: 구동기로 환산 | D10: 단위·한계 일치
A11: 관측 | B11: 최종 24차원 | C11: 순서·정규화 고정 | D11: checkpoint 일치
A12: 실패 종료 | B12: 기울기·접촉·NaN | C12: 조건별 로그 분리 | D12: 정상 종료 구분

Sheet 47_스워브반전
A1: [슬라이드 47] 스워브: 조향 반전과 증상별 수정
A2: 출처: 선생님 공유 슬라이드 「팀별 로봇 미로 주행 — 보상 설계·cuVSLAM·Nav2 실습」 · 회색 = 슬라이드 예시(M38 시연), 노란색 = 우리 팀이 관찰해서 채울 칸
A4: 상황 / 항목 | B4: 기준 / 예시 | C4: 조정 방향 | D4: 확인할 결과 | E4: 우리 로봇 설정값 | F4: 관찰·측정 결과 | G4: 판정 | H4: 근거(로그·영상·파일) | I4: 담당 | J4: 날짜 | K4: 메모
A5: 조향 ±90° 제한 | B5: theta±pi, 속도 반전 | C5: 각도와 부호 동시 수정 | D5: 같은 굴림 방향
A6: 경계에서 채터링 | B6: 시연 hold=0.06 rad | C6: 작게 조정·재시험 | D6: 분기 전환 횟수
A7: 조향 속도 한계 | B7: 시연 1 rad/s | C7: 실제 구동 한계 반영 | D7: 목표·실제 지연
A8: 정렬 전 바퀴 회전 | B8: max(0, cos(error)) | C8: 정렬 동안 감속 | D8: 횡미끄럼·정체
A9: 전진인데 회전 | B9: 모듈 순서·부호 | C9: 한 바퀴씩 확인 | D9: 대칭 속도
A10: 횡이동이 대각선 | B10: 조향 영점·beta | C10: USD 축 다시 측정 | D10: vy 단독 변위
A11: 코너에서 떨림 | B11: 분기·조향 지연 | C11: 저속·각도 로그 | D11: 반전 횟수
A12: 명령은 큰데 정지 | B12: 접촉·토크·슬립 | C12: 보상보다 물리 우선 | D12: 실제 관절·속도

Sheet 48_스워브Nav2
A1: [슬라이드 48] 부록: 스워브와 Nav2 연결
A2: 출처: 선생님 공유 슬라이드 「팀별 로봇 미로 주행 — 보상 설계·cuVSLAM·Nav2 실습」 · 회색 = 슬라이드 예시(M38 시연), 노란색 = 우리 팀이 관찰해서 채울 칸
A4: 상황 / 항목 | B4: 기준 / 예시 | C4: 조정 방향 | D4: 확인할 결과 | E4: 우리 로봇 설정값 | F4: 관찰·측정 결과 | G4: 판정 | H4: 근거(로그·영상·파일) | I4: 담당 | J4: 날짜 | K4: 메모
A5: Nav2 출력 | B5: body vx, vy, wz | C5: 메시지 타입 확인 | D5: Twist / Stamped
A6: Omni 모델 | B6: 횡이동 허용 | C6: vy 제한도 지정 | D6: 역기구학 연결
A7: 실제 odom | B7: 센서 기반 속도 | C7: 명령 복사 금지 | D7: 실제 이동 반영
A8: 명령 중재 | B8: Nav2 또는 PPO | C8: 한 모드만 활성화 | D8: 만료·손실 시 정지

Sheet 49_동역학조향
A1: [슬라이드 49] 동역학·조향: 문제와 수정 사례
A2: 출처: 선생님 공유 슬라이드 「팀별 로봇 미로 주행 — 보상 설계·cuVSLAM·Nav2 실습」 · 회색 = 슬라이드 예시(M38 시연), 노란색 = 우리 팀이 관찰해서 채울 칸
A4: 항목 / 증상 | B4: 원인 | C4: 현재 처리 | D4: 실물 확인 / 기준 | E4: 우리 로봇 설정값 | F4: 관찰·측정 결과 | G4: 판정 | H4: 근거(로그·영상·파일) | I4: 담당 | J4: 날짜 | K4: 메모
A5: 바퀴 관성 | B5: COM 축 밖 | C5: 동심 관성 overlay | D5: 질량·관성 실측
A6: 기어·속도 | B6: 전후 단위 혼동 | C6: 차체 0.95 m/s | D6: RPM·반경 확인
A7: 급제동 | B7: 차체 기울기 | C7: 바퀴 slew 제한 | D7: 정지거리·전류
A8: 코너 속도 | B8: 조향 중 경로 이탈 | C8: 곡률·제동 제한 | D8: 시간·접촉 비교
A9: 정지 중 회전 | B9: 0속도 방향 계산 | C9: 조향 유지·감속 | D9: 재정렬 감소
A10: 비대칭 가속 | B10: 모듈별 정렬 차이 | C10: 감속→동시 정렬 | D10: yaw·이탈 검사
A11: 180° 분기 | B11: 임시 조향 끝단 | C11: 차체 yaw −45° | D11: 실물 범위 실측
A12: 팔·차체 정지 | B12: 시야 제어 결합 | C12: 평소 동시 제어 | D12: 오류 재획득 예외

Sheet 50_미로결과
A1: [슬라이드 50] 두 미로: 실제 영상 폐루프 검증
A2: 출처: 선생님 공유 슬라이드 「팀별 로봇 미로 주행 — 보상 설계·cuVSLAM·Nav2 실습」 · 회색 = 슬라이드 예시(M38 시연), 노란색 = 우리 팀이 관찰해서 채울 칸
A4: 실행 | B4: 미로 | C4: 완주 시간 (s) | D4: 실시간 배율 | E4: 최고 속도 (m/s) | F4: 목표 오차 (cm) | G4: 비바퀴 접촉 (N) | H4: 판정 (자동) | I4: 근거(로그·영상) | J4: 메모
A5: 예시: 첫 미로 GUI 1 | B5: 첫 미로 | C5: 60.45 | D5: 1.0003 | E5: 0.919 | F5: 4.13 | G5: 0 | H5: =IF(OR(E5="",F5="",G5=""),"",IF(AND(F5/100<02_완료기준!$B$5,E5<=02_완료기준!$B$6,G5<=02_완료기준!$B$7),"통과","실패")) -> 통과
A6: 예시: 첫 미로 GUI 2 | B6: 첫 미로 | C6: 63.18 | D6: 1.0002 | E6: 0.922 | F6: 4.25 | G6: 0 | H6: =IF(OR(E6="",F6="",G6=""),"",IF(AND(F6/100<02_완료기준!$B$5,E6<=02_완료기준!$B$6,G6<=02_완료기준!$B$7),"통과","실패")) -> 통과
A7: 예시: 두 번째 미로 | B7: 두 번째 미로 | C7: 57.4 | D7: 0.9993 | E7: 0.824 | F7: 4.43 | G7: 0 | H7: =IF(OR(E7="",F7="",G7=""),"",IF(AND(F7/100<02_완료기준!$B$5,E7<=02_완료기준!$B$6,G7<=02_완료기준!$B$7),"통과","실패")) -> 통과
A8: 우리 1회 | H8: =IF(OR(E8="",F8="",G8=""),"",IF(AND(F8/100<02_완료기준!$B$5,E8<=02_완료기준!$B$6,G8<=02_완료기준!$B$7),"통과","실패"))
A9: 우리 2회 | H9: =IF(OR(E9="",F9="",G9=""),"",IF(AND(F9/100<02_완료기준!$B$5,E9<=02_완료기준!$B$6,G9<=02_완료기준!$B$7),"통과","실패"))
A10: 우리 3회 | H10: =IF(OR(E10="",F10="",G10=""),"",IF(AND(F10/100<02_완료기준!$B$5,E10<=02_완료기준!$B$6,G10<=02_완료기준!$B$7),"통과","실패"))
A11: 우리 4회 | H11: =IF(OR(E11="",F11="",G11=""),"",IF(AND(F11/100<02_완료기준!$B$5,E11<=02_완료기준!$B$6,G11<=02_완료기준!$B$7),"통과","실패"))
A12: 우리 5회 | H12: =IF(OR(E12="",F12="",G12=""),"",IF(AND(F12/100<02_완료기준!$B$5,E12<=02_완료기준!$B$6,G12<=02_완료기준!$B$7),"통과","실패"))
A13: 우리 6회 | H13: =IF(OR(E13="",F13="",G13=""),"",IF(AND(F13/100<02_완료기준!$B$5,E13<=02_완료기준!$B$6,G13<=02_완료기준!$B$7),"통과","실패"))
A14: 우리 7회 | H14: =IF(OR(E14="",F14="",G14=""),"",IF(AND(F14/100<02_완료기준!$B$5,E14<=02_완료기준!$B$6,G14<=02_완료기준!$B$7),"통과","실패"))
A15: 우리 8회 | H15: =IF(OR(E15="",F15="",G15=""),"",IF(AND(F15/100<02_완료기준!$B$5,E15<=02_완료기준!$B$6,G15<=02_완료기준!$B$7),"통과","실패"))
A16: 우리 9회 | H16: =IF(OR(E16="",F16="",G16=""),"",IF(AND(F16/100<02_완료기준!$B$5,E16<=02_완료기준!$B$6,G16<=02_완료기준!$B$7),"통과","실패"))
A17: 우리 10회 | H17: =IF(OR(E17="",F17="",G17=""),"",IF(AND(F17/100<02_완료기준!$B$5,E17<=02_완료기준!$B$6,G17<=02_완료기준!$B$7),"통과","실패"))
A18: 우리 11회 | H18: =IF(OR(E18="",F18="",G18=""),"",IF(AND(F18/100<02_완료기준!$B$5,E18<=02_완료기준!$B$6,G18<=02_완료기준!$B$7),"통과","실패"))
A19: 우리 12회 | H19: =IF(OR(E19="",F19="",G19=""),"",IF(AND(F19/100<02_완료기준!$B$5,E19<=02_완료기준!$B$6,G19<=02_완료기준!$B$7),"통과","실패"))
A21: 판정은 「02_완료기준」의 목표값(오차 < 0.10 m, 속도 ≤ 0.951 m/s, 접촉 ≤ 0.5 N)으로 자동 계산. 회색 3행은 슬라이드 시연 결과(2026-10-26, v5 PPO + EKF·AMCL)

Sheet 51_센서누락
A1: [슬라이드 51] 센서 누락: 정지와 추적 재획득
A2: 출처: 선생님 공유 슬라이드 「팀별 로봇 미로 주행 — 보상 설계·cuVSLAM·Nav2 실습」 · 회색 = 슬라이드 예시(M38 시연), 노란색 = 우리 팀이 관찰해서 채울 칸
A4: 시험 | B4: 누락 조건 | C4: 정지까지 시간 (s) | D4: 재개·재획득 | E4: 접촉 (N) | F4: 판정 | G4: 측정 방법(ROS 주입/실물) | H4: 근거(로그·영상) | I4: 메모
A5: 예시: IMU 2 누락 | B5: 4 s부터 2 s 누락 | C5: 0.355 | D5: 정지·재개 | E5: 0 | F5: 통과 | G5: ROS 주입 오류 시험
A6: 예시: 카메라 누락 | B6: 4 s부터 2.5 s 누락 | C6: 0.355 | D6: 정지·재개 | E6: 0 | F6: 통과 | G6: ROS 주입 오류 시험
A7: 예시: VO 재획득 | B7: 정지 확인 → reset → 안정 | D7: 카메라 시험 reset 1회, EKF 증분으로 좌표 연결 | F7: 통과 | G7: ROS 주입 오류 시험
A8: IMU 1 누락
A9: IMU 2 누락
A10: 카메라 누락
A11: VO 재획득
A12: 엔코더 누락
A13: 라이다/깊이 scan 누락
A14: (추가 시험)
A15: (추가 시험)
